### 1. **Xử lý lỗi (Error handling) là quan trọng:**
```python
# Ví dụ: Chương trình yêu cầu nhập một số nguyên
try:
    num = int(input("Nhập một số nguyên: "))
    print(f"Số bạn vừa nhập là: {num}")
except ValueError:
    print("Lỗi: Bạn phải nhập một số nguyên!")
```
**Giải thích:** Nếu người dùng nhập một chuỗi không phải là số, chương trình sẽ không bị crash mà sẽ thông báo lỗi.

### 2. **Cấu trúc `try-except`:**
```python
try:
    num = int(input("Nhập một số nguyên: "))
    result = 10 / num
except ValueError:
    print("Lỗi: Bạn phải nhập một số nguyên!")
except ZeroDivisionError:
    print("Lỗi: Không thể chia cho 0!")
else:
    print(f"Kết quả của phép chia là: {result}")
finally:
    print("Khối lệnh finally luôn được thực thi.")
```
**Giải thích:** 
- `try`: Chứa code có thể gây ra lỗi.
- `except`: Xử lý các lỗi cụ thể.
- `else`: Chạy khi không có lỗi.
- `finally`: Luôn chạy dù có lỗi hay không.

### 3. **Ví dụ về lỗi và cách xử lý:**

#### a. **Lỗi nhập liệu không phải là số (ValueError):**
```python
try:
    num = int(input("Nhập một số nguyên: "))
    print(f"Số bạn vừa nhập là: {num}")
except ValueError as ve:
    print(f"Lỗi: {ve}")
```
**Giải thích:** Nếu người dùng nhập một chuỗi không phải là số, lỗi `ValueError` sẽ được bắt và thông báo lỗi sẽ được in ra.

#### b. **Lỗi chia cho 0 (ZeroDivisionError):**
```python
try:
    num = int(input("Nhập một số nguyên khác 0: "))
    result = 10 / num
    print(f"Kết quả của phép chia là: {result}")
except ZeroDivisionError:
    print("Lỗi: Không thể chia cho 0!")
```
**Giải thích:** Nếu người dùng nhập số 0, lỗi `ZeroDivisionError` sẽ được bắt và thông báo lỗi sẽ được in ra.

#### c. **Sử dụng `as` để lấy thông tin lỗi:**
```python
try:
    num = int(input("Nhập một số nguyên: "))
    result = 10 / num
except ValueError as ve:
    print(f"Lỗi nhập liệu: {ve}")
except ZeroDivisionError as zde:
    print(f"Lỗi chia cho 0: {zde}")
```
**Giải thích:** Sử dụng `as` để lấy đối tượng lỗi và in ra thông tin chi tiết về lỗi.

### 4. **Thứ tự `except`:**
```python
try:
    num = int(input("Nhập một số nguyên: "))
    result = 10 / num
except Exception as e:
    print(f"Lỗi tổng quát: {e}")
except ValueError:
    print("Lỗi: Bạn phải nhập một số nguyên!")
```
**Giải thích:** Khối `except Exception` sẽ bắt mọi lỗi, nhưng nó phải được đặt sau các khối `except` cụ thể. Nếu đặt trước, các khối `except` cụ thể sẽ không bao giờ được thực thi.

### 5. **`else` và `finally`:**
```python
try:
    num = int(input("Nhập một số nguyên: "))
    result = 10 / num
except ValueError:
    print("Lỗi: Bạn phải nhập một số nguyên!")
except ZeroDivisionError:
    print("Lỗi: Không thể chia cho 0!")
else:
    print(f"Kết quả của phép chia là: {result}")
finally:
    print("Khối lệnh finally luôn được thực thi.")
```
**Giải thích:** 
- `else`: Chỉ chạy khi không có lỗi trong `try`.
- `finally`: Luôn chạy sau `try`, dù có lỗi hay không.

### 6. **`raise` exception:**
```python
def check_age(age):
    if age < 0:
        raise ValueError("Tuổi không thể là số âm!")
    elif age > 120:
        raise ValueError("Tuổi không thể lớn hơn 120!")
    else:
        print(f"Tuổi hợp lệ: {age}")

try:
    check_age(-5)
except ValueError as ve:
    print(f"Lỗi: {ve}")
```
**Giải thích:** Hàm `check_age` kiểm tra tuổi và chủ động ném ra lỗi `ValueError` nếu tuổi không hợp lệ. Lỗi này được bắt và xử lý trong khối `except`.

